<?xml version="1.0" encoding="utf-8"?>
<mujoco model="triangular_base">

	<!-- set some defaults for units and lighting -->
	<compiler angle="degree" meshdir="./stl_exports/"/>

	<option timestep="0.001"/>

	<!-- import our stl files -->
	<asset>
		<mesh name="baseplate" file="baseplate_robot.stl" />
		<mesh name="wheel" file="wheel_for_mujoco.stl" />
	</asset>

	<!-- define our robot model -->
	<worldbody>
		<!-- set up a light pointing down on the robot -->
		<light directional="true" pos="-0.5 0.5 3" dir="0 0 -1" />
		<camera name="track_camera" mode="targetbodycom" target="base" euler="0 0 0" fovy="60" pos="0 0 2" />
		<!-- add a floor so we don't stare off into the abyss -->
		<geom name="floor" pos="0 0 1" size="50 50 50" type="plane" rgba="1 0.83 0.61 0.5"/>

		<!-- start building our model -->
		<body name="base" pos="0 0 0">
			<joint name="joint_base" type="free" axis="0 0 0"/>
			<geom name="baseplate_robot" type="mesh" mesh="baseplate" pos="0 0 1"/>
			<inertial pos="0 0 1" mass="150" diaginertia="1 1 1"/>

			<!-- Attach wheels to the main body -->
			<!--							cos(15 degree)	sin(15 degree)-->
			<body name="wheel_1_body" pos=".4 -.2325 1.05" quat="0.5 1 0 .866">
				<joint name="joint1" type="hinge" axis="0 0 1" damping="5"/>
				<geom type="cylinder" size=".1 .0125 .01"/>

				<!--<geom type="sphere" rgba="0 0 1 1" size=".1"/>-->
				<inertial pos="0 0 1" mass="5" diaginertia="0.5 0.5 1"/>

				<body name="wheel_1_omni0" pos="0 -.085 0" quat="0 -1 0 1">
					<joint name="joint1_omni0" type="hinge" axis="0 0 1" damping="0.1"/>
					<geom type="cylinder" size=".02 .02 .02" contype="1" conaffinity="0"/>

					<!--<geom type="sphere" rgba="0 0 1 1" size=".1"/>-->
					<inertial pos="0 0 1" mass="0.001" diaginertia="0.00001 0.00001 0.00001"/>

				</body>

				<body name="wheel_1_omni1" pos="0 .085 0" quat="0 -1 0 1">
					<joint name="joint1_omni1" type="hinge" axis="0 0 1" damping="0.1"/>
					<geom type="cylinder" size=".02 .02 .02" contype="1" conaffinity="0"/>

					<!--<geom type="sphere" rgba="0 0 1 1" size=".1"/>-->
					<inertial pos="0 0 1" mass="0.001" diaginertia="0.00001 0.00001 0.00001"/>

				</body>

				<body name="wheel_1_omni2" pos=".085 0 0" quat="1 1 0 0">
					<joint name="joint1_omni2" type="hinge" axis="0 0 1" damping="0.1"/>
					<geom type="cylinder" size=".02 .02 .02" contype="1" conaffinity="0"/>

					<!--<geom type="sphere" rgba="0 0 1 1" size=".1"/>-->
					<inertial pos="0 0 1" mass="5" diaginertia="0.00001 0.00001 0.00001"/>

				</body>

				<body name="wheel_1_omni3" pos="-.085 0 0" quat="1 1 0 0">
					<joint name="joint1_omni3" type="hinge" axis="0 0 1" damping="0.1"/>
					<geom type="cylinder" size=".02 .02 .02" contype="1" conaffinity="0"/>

					<!--<geom type="sphere" rgba="0 0 1 1" size=".1"/>-->
					<inertial pos="0 0 1" mass="0.001" diaginertia="0.00001 0.00001 0.00001"/>

				</body>

				<body name="wheel_1_omni4" pos="-.06 -.06 0" quat="0.676 0.227 0.661 -.233">
					<joint name="joint1_omni4" type="hinge" axis="0 0 1" damping="0.1"/>
					<geom type="cylinder" size=".02 .02 .02" contype="1" conaffinity="0"/>

					<!--<geom type="sphere" rgba="0 0 1 1" size=".1"/>-->
					<inertial pos="0 0 1" mass="0.001" diaginertia="0.00001 0.00001 0.00001"/>

				</body>

				<body name="wheel_1_omni5" pos=".06 -.06 0" quat="0.661 -0.268 0.645 .274">
					<joint name="joint1_omni5" type="hinge" axis="0 0 1" damping="0.1"/>
					<geom type="cylinder" size=".02 .02 .02" contype="1" conaffinity="0"/>

					<!--<geom type="sphere" rgba="0 0 1 1" size=".1"/>-->
					<inertial pos="0 0 1" mass="0.001" diaginertia="0.00001 0.00001 0.00001"/>

				</body>

				<body name="wheel_1_omni6" pos=".06 .06 0" quat="0.276 -0.642 0.268 .663">
					<joint name="joint1_omni6" type="hinge" axis="0 0 1" damping="0.1"/>
					<geom type="cylinder" size=".02 .02 .02" contype="1" conaffinity="0"/>

					<!--<geom type="sphere" rgba="0 0 1 1" size=".1"/>-->
					<inertial pos="0 0 1" mass="0.001" diaginertia="0.00001 0.00001 0.00001"/>

				</body>

				<body name="wheel_1_omni7" pos="-.06 .06 0" quat="-0.276 -0.642 -0.268 .663">
					<joint name="joint1_omni7" type="hinge" axis="0 0 1" damping="0.1"/>
					<geom type="cylinder" size=".02 .02 .02" contype="1" conaffinity="0"/>

					<!--<geom type="sphere" rgba="0 0 1 1" size=".1"/>-->
					<inertial pos="0 0 1" mass="0.001" diaginertia="0.00001 0.00001 0.00001"/>

				</body>


				<!-- Second Wheel -->

				<body name="wheel_1_body1" pos="0 0 0.03" quat="0.195 0 0 0.975">
					<geom type="cylinder" size=".1 .0125 .01"/>

					<!--<geom type="sphere" rgba="0 0 1 1" size=".1"/>-->
					<inertial pos="0 0 1" mass="5" diaginertia="0.5 0.5 1"/>

					<body name="wheel_1_1omni0" pos="0 -.085 0" quat="0 -1 0 1">
						<joint name="joint1_1omni0" type="hinge" axis="0 0 1" damping="0.1"/>
						<geom type="cylinder" size=".02 .02 .02" contype="1" conaffinity="0"/>

						<!--<geom type="sphere" rgba="0 0 1 1" size=".1"/>-->
						<inertial pos="0 0 1" mass="1" diaginertia="0.00001 0.00001 0.00001"/>

					</body>

					<body name="wheel_1_1omni1" pos="0 .085 0" quat="0 -1 0 1">
						<joint name="joint1_1omni1" type="hinge" axis="0 0 1" damping="0.1"/>
						<geom type="cylinder" size=".02 .02 .02" contype="1" conaffinity="0"/>

						<!--<geom type="sphere" rgba="0 0 1 1" size=".1"/>-->
						<inertial pos="0 0 1" mass="0.001" diaginertia="0.00001 0.00001 0.00001"/>
					</body>

					<body name="wheel_1_1omni2" pos=".085 0 0" quat="1 1 0 0">
						<joint name="joint1_1omni2" type="hinge" axis="0 0 1" damping="0.1"/>
						<geom type="cylinder" size=".02 .02 .02" contype="1" conaffinity="0"/>

						<!--<geom type="sphere" rgba="0 0 1 1" size=".1"/>-->
						<inertial pos="0 0 1" mass="0.001" diaginertia="0.00001 0.00001 0.00001"/>

					</body>

					<body name="wheel_1_1omni3" pos="-.085 0 0" quat="1 1 0 0">
						<joint name="joint1_1omni3" type="hinge" axis="0 0 1" damping="0.1"/>
						<geom type="cylinder" size=".02 .02 .02" contype="1" conaffinity="0"/>

						<!--<geom type="sphere" rgba="0 0 1 1" size=".1"/>-->
						<inertial pos="0 0 1" mass="0.001" diaginertia="0.00001 0.00001 0.00001"/>

					</body>

					<body name="wheel_1_1omni4" pos="-.06 -.06 0" quat="0.676 0.227 0.661 -.233">
						<joint name="joint1_1omni4" type="hinge" axis="0 0 1" damping="0.1"/>
						<geom type="cylinder" size=".02 .02 .02" contype="1" conaffinity="0"/>

						<!--<geom type="sphere" rgba="0 0 1 1" size=".1"/>-->
						<inertial pos="0 0 1" mass="0.001" diaginertia="0.00001 0.00001 0.00001"/>

					</body>

					<body name="wheel_1_1omni5" pos=".06 -.06 0" quat="0.661 -0.268 0.645 .274">
						<joint name="joint1_1omni5" type="hinge" axis="0 0 1" damping="0.1"/>
						<geom type="cylinder" size=".02 .02 .02" contype="1" conaffinity="0"/>

						<!--<geom type="sphere" rgba="0 0 1 1" size=".1"/>-->
						<inertial pos="0 0 1" mass="0.001" diaginertia="0.00001 0.00001 0.00001"/>

					</body>

					<body name="wheel_1_1omni6" pos=".06 .06 0" quat="0.276 -0.642 0.268 .663">
						<joint name="joint1_1omni6" type="hinge" axis="0 0 1" damping="0.1"/>
						<geom type="cylinder" size=".02 .02 .02" contype="1" conaffinity="0"/>

						<!--<geom type="sphere" rgba="0 0 1 1" size=".1"/>-->
						<inertial pos="0 0 1" mass="0.001" diaginertia="0.00001 0.00001 0.00001"/>

					</body>

					<body name="wheel_1_1omni7" pos="-.06 .06 0" quat="-0.276 -0.642 -0.268 .663">
						<joint name="joint1_1omni7" type="hinge" axis="0 0 1" damping="0.1"/>
						<geom type="cylinder" size=".02 .02 .02" contype="1" conaffinity="0"/>

						<!--<geom type="sphere" rgba="0 0 1 1" size=".1"/>-->
						<inertial pos="0 0 1" mass="0.001" diaginertia="0.00001 0.00001 0.00001"/>

					</body>

				</body>


			</body>

			<body name="wheel_2_body" pos="0 .46 1.05" quat="1 1 0 0"> <!-- This quat makes cylinder parallel with 3D y-axis and straight up -->
				<joint name="joint2" type="hinge" axis="0 0 1" damping="5"/> <!-- GOOD -->
				<geom type="cylinder" size=".1 .01 .01"/>
				<inertial pos="0 0 1" mass="5" diaginertia="0.5 0.5 1"/>

				<body name="wheel_2_omni0" pos="0 -.085 0" quat="0 -1 0 1">
					<joint name="joint2_omni0" type="hinge" axis="0 0 1" damping="0.1"/>
					<geom type="cylinder" size=".02 .02 .02" contype="1" conaffinity="0"/>

					<!--<geom type="sphere" rgba="0 0 1 1" size=".1"/>-->
					<inertial pos="0 0 1" mass="0.001" diaginertia="0.00001 0.00001 0.00001"/>

				</body>

				<body name="wheel_2_omni1" pos="0 .085 0" quat="0 -1 0 1">
					<joint name="joint2_omni1" type="hinge" axis="0 0 1" damping="0.1"/>
					<geom type="cylinder" size=".02 .02 .02" contype="1" conaffinity="0"/>

					<!--<geom type="sphere" rgba="0 0 1 1" size=".1"/>-->
					<inertial pos="0 0 1" mass="0.001" diaginertia="0.00001 0.00001 0.00001"/>

				</body>

				<body name="wheel_2_omni2" pos=".085 0 0" quat="1 1 0 0">
					<joint name="joint2_omni2" type="hinge" axis="0 0 1" damping="0.1"/>
					<geom type="cylinder" size=".02 .02 .02" contype="1" conaffinity="0"/>

					<!--<geom type="sphere" rgba="0 0 1 1" size=".1"/>-->
					<inertial pos="0 0 1" mass="0.001" diaginertia="0.00001 0.00001 0.00001"/>

				</body>

				<body name="wheel_2_omni3" pos="-.085 0 0" quat="1 1 0 0">
					<joint name="joint2_omni3" type="hinge" axis="0 0 1" damping="0.1"/>
					<geom type="cylinder" size=".02 .02 .02" contype="1" conaffinity="0"/>

					<!--<geom type="sphere" rgba="0 0 1 1" size=".1"/>-->
					<inertial pos="0 0 1" mass="0.001" diaginertia="0.00001 0.00001 0.00001"/>

				</body>

				<body name="wheel_2_omni4" pos="-.06 -.06 0" quat="0.676 0.227 0.661 -.233">
					<joint name="joint2_omni4" type="hinge" axis="0 0 1" damping="0.1"/>
					<geom type="cylinder" size=".02 .02 .02" contype="1" conaffinity="0"/>

					<!--<geom type="sphere" rgba="0 0 1 1" size=".1"/>-->
					<inertial pos="0 0 1" mass="0.001" diaginertia="0.00001 0.00001 0.00001"/>

				</body>

				<body name="wheel_2_omni5" pos=".06 -.06 0" quat="0.661 -0.268 0.645 .274">
					<joint name="joint2_omni5" type="hinge" axis="0 0 1" damping="0.1"/>
					<geom type="cylinder" size=".02 .02 .02" contype="1" conaffinity="0"/>

					<!--<geom type="sphere" rgba="0 0 1 1" size=".1"/>-->
					<inertial pos="0 0 1" mass="0.001" diaginertia="0.00001 0.00001 0.00001"/>

				</body>

				<body name="wheel_2_omni6" pos=".06 .06 0" quat="0.276 -0.642 0.268 .663">
					<joint name="joint2_omni6" type="hinge" axis="0 0 1" damping="0.1"/>
					<geom type="cylinder" size=".02 .02 .02" contype="1" conaffinity="0"/>

					<!--<geom type="sphere" rgba="0 0 1 1" size=".1"/>-->
					<inertial pos="0 0 1" mass="0.001" diaginertia="0.00001 0.00001 0.00001"/>

				</body>

				<body name="wheel_2_omni7" pos="-.06 .06 0" quat="-0.276 -0.642 -0.268 .663">
					<joint name="joint2_omni7" type="hinge" axis="0 0 1" damping="0.1"/>
					<geom type="cylinder" size=".02 .02 .02" contype="1" conaffinity="0"/>

					<!--<geom type="sphere" rgba="0 0 1 1" size=".1"/>-->
					<inertial pos="0 0 1" mass="0.001" diaginertia="0.00001 0.00001 0.00001"/>

				</body>

				<!-- Second Wheel -->

				<!-- Second Second Wheel -->

				<body name="wheel_2_body1" pos="0 0 0.03" quat="0.195 0 0 0.975">
					<geom type="cylinder" size=".1 .0125 .01"/>

					<!--<geom type="sphere" rgba="0 0 1 1" size=".1"/>-->
					<inertial pos="0 0 1" mass="5" diaginertia="0.5 0.5 1"/>

					<body name="wheel_2_1omni0" pos="0 -.085 0" quat="0 -1 0 1">
						<joint name="joint2_1omni0" type="hinge" axis="0 0 1" damping="0.1"/>
						<geom type="cylinder" size=".02 .02 .02" contype="1" conaffinity="0"/>

						<!--<geom type="sphere" rgba="0 0 1 1" size=".1"/>-->
						<inertial pos="0 0 1" mass="0.001" diaginertia="0.00001 0.00001 0.00001"/>

					</body>

					<body name="wheel_2_1omni1" pos="0 .085 0" quat="0 -1 0 1">
						<joint name="joint2_1omni1" type="hinge" axis="0 0 1" damping="0.1"/>
						<geom type="cylinder" size=".02 .02 .02" contype="1" conaffinity="0"/>

						<!--<geom type="sphere" rgba="0 0 1 1" size=".1"/>-->
						<inertial pos="0 0 1" mass="0.001" diaginertia="0.00001 0.00001 0.00001"/>
					</body>

					<body name="wheel_2_1omni2" pos=".085 0 0" quat="1 1 0 0">
						<joint name="joint2_1omni2" type="hinge" axis="0 0 1" damping="0.1"/>
						<geom type="cylinder" size=".02 .02 .02" contype="1" conaffinity="0"/>

						<!--<geom type="sphere" rgba="0 0 1 1" size=".1"/>-->
						<inertial pos="0 0 1" mass="0.001" diaginertia="0.00001 0.00001 0.00001"/>

					</body>

					<body name="wheel_2_1omni3" pos="-.085 0 0" quat="1 1 0 0">
						<joint name="joint2_1omni3" type="hinge" axis="0 0 1" damping="0.1"/>
						<geom type="cylinder" size=".02 .02 .02" contype="1" conaffinity="0"/>

						<!--<geom type="sphere" rgba="0 0 1 1" size=".1"/>-->
						<inertial pos="0 0 1" mass="0.001" diaginertia="0.00001 0.00001 0.00001"/>

					</body>

					<body name="wheel_2_1omni4" pos="-.06 -.06 0" quat="0.676 0.227 0.661 -.233">
						<joint name="joint2_1omni4" type="hinge" axis="0 0 1" damping="0.1"/>
						<geom type="cylinder" size=".02 .02 .02" contype="1" conaffinity="0"/>

						<!--<geom type="sphere" rgba="0 0 1 1" size=".1"/>-->
						<inertial pos="0 0 1" mass="0.001" diaginertia="0.00001 0.00001 0.00001"/>

					</body>

					<body name="wheel_2_1omni5" pos=".06 -.06 0" quat="0.661 -0.268 0.645 .274">
						<joint name="joint2_1omni5" type="hinge" axis="0 0 1" damping="0.1"/>
						<geom type="cylinder" size=".02 .02 .02" contype="1" conaffinity="0"/>

						<!--<geom type="sphere" rgba="0 0 1 1" size=".1"/>-->
						<inertial pos="0 0 1" mass="0.001" diaginertia="0.00001 0.00001 0.00001"/>

					</body>

					<body name="wheel_2_1omni6" pos=".06 .06 0" quat="0.276 -0.642 0.268 .663">
						<joint name="joint2_1omni6" type="hinge" axis="0 0 1" damping="0.1"/>
						<geom type="cylinder" size=".02 .02 .02" contype="1" conaffinity="0"/>

						<!--<geom type="sphere" rgba="0 0 1 1" size=".1"/>-->
						<inertial pos="0 0 1" mass="0.001" diaginertia="0.00001 0.00001 0.00001"/>

					</body>

					<body name="wheel_2_1omni7" pos="-.06 .06 0" quat="-0.276 -0.642 -0.268 .663">
						<joint name="joint2_1omni7" type="hinge" axis="0 0 1" damping="0.1"/>
						<geom type="cylinder" size=".02 .02 .02" contype="1" conaffinity="0"/>

						<!--<geom type="sphere" rgba="0 0 1 1" size=".1"/>-->
						<inertial pos="0 0 1" mass="0.001" diaginertia="0.00001 0.00001 0.00001"/>

					</body>
				</body>
			</body>

			<body name="wheel_3_body" pos="-.4 -.2325 1.05" quat="-0.5 1 0 .866">
				<joint name="joint3" type="hinge" axis="0 0 1" damping="5"/>
				<geom type="cylinder" size=".1 .01 .01"/>
				<inertial pos="0 0 1" mass="5" diaginertia="0.5 0.5 1"/>

				<body name="wheel_3_omni0" pos="0 -.085 0" quat="0 -1 0 1">
					<joint name="joint3_omni0" type="hinge" axis="0 0 1" damping="0.1" limited="false" actuatorfrclimited="false"/>
					<geom type="cylinder" size=".02 .02 .02" contype="1" conaffinity="0"/>

					<!--<geom type="sphere" rgba="0 0 1 1" size=".1"/>-->
					<inertial pos="0 0 1" mass="0.001" diaginertia="0.00001 0.00001 0.00001"/>

				</body>

				<body name="wheel_3_omni1" pos="0 .085 0" quat="0 -1 0 1">
					<joint name="joint3_omni1" type="hinge" axis="0 0 1" damping="0.1" limited="false" actuatorfrclimited="false"/>
					<geom type="cylinder" size=".02 .02 .02" contype="1" conaffinity="0"/>

					<!--<geom type="sphere" rgba="0 0 1 1" size=".1"/>-->
					<inertial pos="0 0 1" mass="0.001" diaginertia="0.00001 0.00001 0.00001"/>

				</body>

				<body name="wheel_3_omni2" pos=".085 0 0" quat="1 1 0 0">
					<joint name="joint3_omni2" type="hinge" axis="0 0 1" damping="0.1" limited="false" actuatorfrclimited="false"/>
					<geom type="cylinder" size=".02 .02 .02" contype="1" conaffinity="0"/>

					<!--<geom type="sphere" rgba="0 0 1 1" size=".1"/>-->
					<inertial pos="0 0 1" mass="0.001" diaginertia="0.00001 0.00001 0.00001"/>

				</body>

				<body name="wheel_3_omni3" pos="-.085 0 0" quat="1 1 0 0">
					<joint name="joint3_omni3" type="hinge" axis="0 0 1" damping="0.1" limited="false" actuatorfrclimited="false"/>
					<geom type="cylinder" size=".02 .02 .02" contype="1" conaffinity="0"/>

					<!--<geom type="sphere" rgba="0 0 1 1" size=".1"/>-->
					<inertial pos="0 0 1" mass="0.001" diaginertia="0.00001 0.00001 0.00001"/>

				</body>

				<body name="wheel_3_omni4" pos="-.06 -.06 0" quat="0.676 0.227 0.661 -.233">
					<joint name="joint3_omni4" type="hinge" axis="0 0 1" damping="0.1" limited="false" actuatorfrclimited="false"/>
					<geom type="cylinder" size=".02 .02 .02" contype="1" conaffinity="0"/>

					<!--<geom type="sphere" rgba="0 0 1 1" size=".1"/>-->
					<inertial pos="0 0 1" mass="0.001" diaginertia="0.00001 0.00001 0.00001"/>

				</body>

				<body name="wheel_3_omni5" pos=".06 -.06 0" quat="0.661 -0.268 0.645 .274">
					<joint name="joint3_omni5" type="hinge" axis="0 0 1" damping="0.1" limited="false" actuatorfrclimited="false"/>
					<geom type="cylinder" size=".02 .02 .02" contype="1" conaffinity="0"/>

					<!--<geom type="sphere" rgba="0 0 1 1" size=".1"/>-->
					<inertial pos="0 0 1" mass="0.001" diaginertia="0.00001 0.00001 0.00001"/>

				</body>

				<body name="wheel_3_omni6" pos=".06 .06 0" quat="0.276 -0.642 0.268 .663">
					<joint name="joint3_omni6" type="hinge" axis="0 0 1" damping="0.1" limited="false" actuatorfrclimited="false"/>
					<geom type="cylinder" size=".02 .02 .02" contype="1" conaffinity="0"/>

					<!--<geom type="sphere" rgba="0 0 1 1" size=".1"/>-->
					<inertial pos="0 0 1" mass="0.001" diaginertia="0.00001 0.00001 0.00001"/>

				</body>

				<body name="wheel_3_omni7" pos="-.06 .06 0" quat="-0.276 -0.642 -0.268 .663">
					<joint name="joint3_omni7" type="hinge" axis="0 0 1" damping="0.1" limited="false" actuatorfrclimited="false"/>
					<geom type="cylinder" size=".02 .02 .02" contype="1" conaffinity="0"/>

					<!--<geom type="sphere" rgba="0 0 1 1" size=".1"/>-->
					<inertial pos="0 0 1" mass="0.001" diaginertia="0.00001 0.00001 0.00001"/>

				</body>

				<!-- Second Wheel -->

				<!-- Second Wheel -->

			<body name="wheel_3_body1" pos="0 0 0.03" quat="0.195 0 0 0.975">
				<geom type="cylinder" size=".1 .0125 .01"/>

				<!--<geom type="sphere" rgba="0 0 1 1" size=".1"/>-->
				<inertial pos="0 0 1" mass="1" diaginertia="0.5 0.5 1"/>

				<body name="wheel_3_1omni0" pos="0 -.085 0" quat="0 -1 0 1">
					<joint name="joint3_1omni0" type="hinge" axis="0 0 1" damping="0.1" limited="false" actuatorfrclimited="false"/>
					<geom type="cylinder" size=".02 .02 .02" contype="1" conaffinity="0"/>

					<!--<geom type="sphere" rgba="0 0 1 1" size=".1"/>-->
					<inertial pos="0 0 1" mass="0.001" diaginertia="0.00001 0.00001 0.00001"/>

				</body>

				<body name="wheel_3_1omni1" pos="0 .085 0" quat="0 -1 0 1">
					<joint name="joint3_1omni1" type="hinge" axis="0 0 1" damping="0.1" limited="false" actuatorfrclimited="false"/>
					<geom type="cylinder" size=".02 .02 .02" contype="1" conaffinity="0"/>

					<!--<geom type="sphere" rgba="0 0 1 1" size=".1"/>-->
					<inertial pos="0 0 1" mass="0.001" diaginertia="0.00001 0.00001 0.00001"/>
				</body>

				<body name="wheel_3_1omni2" pos=".085 0 0" quat="1 1 0 0">
					<joint name="joint3_1omni2" type="hinge" axis="0 0 1" damping="0.1" limited="false" actuatorfrclimited="false"/>
					<geom type="cylinder" size=".02 .02 .02" contype="1" conaffinity="0"/>

					<!--<geom type="sphere" rgba="0 0 1 1" size=".1"/>-->
					<inertial pos="0 0 1" mass="0.001" diaginertia="0.00001 0.00001 0.00001"/>
				</body>

				<body name="wheel_3_1omni3" pos="-.085 0 0" quat="1 1 0 0">
					<joint name="joint3_1omni3" type="hinge" axis="0 0 1" damping="0.1" limited="false" actuatorfrclimited="false"/>
			 		<geom type="cylinder" size=".02 .02 .02" contype="1" conaffinity="0"/>

					<!--<geom type="sphere" rgba="0 0 1 1" size=".1"/>-->
					<inertial pos="0 0 1" mass="0.001" diaginertia="0.00001 0.00001 0.00001"/>
				</body>

				<body name="wheel_3_1omni4" pos="-.06 -.06 0" quat="0.676 0.227 0.661 -.233">
					<joint name="joint3_1omni4" type="hinge" axis="0 0 1" damping="0.1" limited="false" actuatorfrclimited="false"/>
					<geom type="cylinder" size=".02 .02 .02" contype="1" conaffinity="0"/>

					<!--<geom type="sphere" rgba="0 0 1 1" size=".1"/>-->
					<inertial pos="0 0 1" mass="0.001" diaginertia="0.00001 0.00001 0.00001"/>

				</body>

				<body name="wheel_3_1omni5" pos=".06 -.06 0" quat="0.661 -0.268 0.645 .274">
					<joint name="joint3_1omni5" type="hinge" axis="0 0 1" damping="0.1" limited="false" actuatorfrclimited="false"/>
					<geom type="cylinder" size=".02 .02 .02" contype="1" conaffinity="0"/>

					<!--<geom type="sphere" rgba="0 0 1 1" size=".1"/>-->
					<inertial pos="0 0 1" mass="0.001" diaginertia="0.00001 0.00001 0.00001"/>

				</body>

				<body name="wheel_3_1omni6" pos=".06 .06 0" quat="0.276 -0.642 0.268 .663">
					<joint name="joint3_1omni6" type="hinge" axis="0 0 1" damping="0.1" limited="false" actuatorfrclimited="false"/>
					<geom type="cylinder" size=".02 .02 .02" contype="1" conaffinity="0"/>

					<!--<geom type="sphere" rgba="0 0 1 1" size=".1"/>-->
					<inertial pos="0 0 1" mass="0.001" diaginertia="0.00001 0.00001 0.00001"/>

				</body>

				<body name="wheel_3_1omni7" pos="-.06 .06 0" quat="-0.276 -0.642 -0.268 .663">
					<joint name="joint3_1omni7" type="hinge" axis="0 0 1" damping="0.1" limited="false" actuatorfrclimited="false"/>
					<geom type="cylinder" size=".02 .02 .02" contype="1" conaffinity="0"/>

			 		<!--<geom type="sphere" rgba="0 0 1 1" size=".1"/>-->
					<inertial pos="0 0 1" mass="0.001" diaginertia="0.00001 0.00001 0.00001"/>

				</body>

			</body>


			</body>
		</body>
	</worldbody>

	<!-- attach actuators to joints -->
	<actuator>
		<motor name="joint1_motor" joint="joint1" ctrlrange="-75 75.0" ctrllimited="true"/>

		<motor name="joint2_motor" joint="joint2" ctrlrange="-75 75.0" ctrllimited="true"/>

		<motor name="joint3_motor" joint="joint3" ctrlrange="-75 75.0" ctrllimited="true"/>

	</actuator>

  <sensor>

	<actuatorfrc name="joint1_motor" actuator="joint1_motor"/>
	<actuatorfrc name="joint2_motor" actuator="joint2_motor"/>
	<actuatorfrc name="joint3_motor" actuator="joint3_motor"/>
<!--	<actuatorfrc name="damper1" actuator="damper1"/>
	<actuatorfrc name="damper2" actuator="damper2"/>
	<actuatorfrc name="damper3" actuator="damper3"/>-->

	<jointactuatorfrc name="joint1" joint="joint1"/>
	<jointactuatorfrc name="joint2" joint="joint2"/>
	<jointactuatorfrc name="joint3" joint="joint3"/>
  </sensor>

</mujoco>
